Workbook

Sheet Questionnaire_Raw
A1: Student questionnaire — raw responses (export from Google Forms, one row per response)
A2: NO DATA HAS BEEN ENTERED. Every row below is an empty template. Enter only real responses; never estimate. Participant codes (S01…, G01…, A01…) replace all names.
A3: Participant code | B3: Date | C3: Valid? (Y/N) | D3: Q1 Programme | E3: Q2 Hosteller/Day scholar | F3: Q3 Entries per weekday | G3: Q4 How ID carried | H3: Q5 How closely guard looks | I3: Q11a Peak wait time | J3: Q11b Retrieving ID inconvenient (Likert 1-5) | K3: Q6 Times without ID last month | L3: Q7 What happened without ID (multi) | M3: Q8 If refused, what did you do | N3: Q9 Ever lost ID | O3: Q10 Days to replacement / interim access | P3: Q12 Seen other's ID / fake / no check | Q3: Q13a Current check reliable (L) | R3: Q13b Concerned lost card usable (L) | S3: Q13c Perceived security problems (multi) | T3: Q14a Comfortable with entry time recorded (L) | U3: Q14b Want to see own records (L) | V3: Q14c Details OK for guard to see (multi) | W3: Q15a Trust electronic more (L) | X3: Q15b Worried about other uses (L) | Y3: Q15c What would increase trust | Z3: Q16 Ranking: card / phone NFC / QR / visual / other (1-5 each) | AA3: Q17 Phone type | AB3: Q18 Accessibility needs | AC3: Q19 Expectation if ID stops working (multi) | AD3: Q20 Anything else
A4: S01
A5: S02
A6: S03
A7: S04
A8: S05
A9: S06
A10: S07
A11: S08
A12: S09
A13: S10
A14: S11
A15: S12
... A63: S60

Sheet Likert_Summary
A1: Likert summary — formulas count raw sheet; blank until data exists
A2: NO DATA HAS BEEN ENTERED. Every row below is an empty template. Enter only real responses; never estimate. Participant codes (S01…, G01…, A01…) replace all names.
A4: Item | B4: Statement | C4: SD (1) | D4: D (2) | E4: N (3) | F4: A (4) | G4: SA (5) | H4: n | I4: Median
A5: Q11b | B5: Retrieving ID inconvenient (Likert 1-5) | C5: =COUNTIF(Questionnaire_Raw!$J$3:$J$62,1) -> 0 | D5: =COUNTIF(Questionnaire_Raw!$J$3:$J$62,2) -> 0 | E5: =COUNTIF(Questionnaire_Raw!$J$3:$J$62,3) -> 0 | F5: =COUNTIF(Questionnaire_Raw!$J$3:$J$62,4) -> 0 | G5: =COUNTIF(Questionnaire_Raw!$J$3:$J$62,5) -> 0 | H5: =COUNT(Questionnaire_Raw!$J$3:$J$62) -> 0 | I5: =IF(COUNT(Questionnaire_Raw!$J$3:$J$62)=0,"",MEDIAN(Questionnaire_Raw!$J$3:$J$62)) -> 0
A6: Q13a | B6: Current check reliable (L) | C6: =COUNTIF(Questionnaire_Raw!$Q$3:$Q$62,1) -> 0 | D6: =COUNTIF(Questionnaire_Raw!$Q$3:$Q$62,2) -> 0 | E6: =COUNTIF(Questionnaire_Raw!$Q$3:$Q$62,3) -> 0 | F6: =COUNTIF(Questionnaire_Raw!$Q$3:$Q$62,4) -> 0 | G6: =COUNTIF(Questionnaire_Raw!$Q$3:$Q$62,5) -> 0 | H6: =COUNT(Questionnaire_Raw!$Q$3:$Q$62) -> 0 | I6: =IF(COUNT(Questionnaire_Raw!$Q$3:$Q$62)=0,"",MEDIAN(Questionnaire_Raw!$Q$3:$Q$62)) -> 0
A7: Q13b | B7: Concerned lost card usable (L) | C7: =COUNTIF(Questionnaire_Raw!$R$3:$R$62,1) -> 0 | D7: =COUNTIF(Questionnaire_Raw!$R$3:$R$62,2) -> 0 | E7: =COUNTIF(Questionnaire_Raw!$R$3:$R$62,3) -> 0 | F7: =COUNTIF(Questionnaire_Raw!$R$3:$R$62,4) -> 0 | G7: =COUNTIF(Questionnaire_Raw!$R$3:$R$62,5) -> 0 | H7: =COUNT(Questionnaire_Raw!$R$3:$R$62) -> 0 | I7: =IF(COUNT(Questionnaire_Raw!$R$3:$R$62)=0,"",MEDIAN(Questionnaire_Raw!$R$3:$R$62)) -> 0
A8: Q14a | B8: Comfortable with entry time recorded (L) | C8: =COUNTIF(Questionnaire_Raw!$T$3:$T$62,1) -> 0 | D8: =COUNTIF(Questionnaire_Raw!$T$3:$T$62,2) -> 0 | E8: =COUNTIF(Questionnaire_Raw!$T$3:$T$62,3) -> 0 | F8: =COUNTIF(Questionnaire_Raw!$T$3:$T$62,4) -> 0 | G8: =COUNTIF(Questionnaire_Raw!$T$3:$T$62,5) -> 0 | H8: =COUNT(Questionnaire_Raw!$T$3:$T$62) -> 0 | I8: =IF(COUNT(Questionnaire_Raw!$T$3:$T$62)=0,"",MEDIAN(Questionnaire_Raw!$T$3:$T$62)) -> 0
A9: Q14b | B9: Want to see own records (L) | C9: =COUNTIF(Questionnaire_Raw!$U$3:$U$62,1) -> 0 | D9: =COUNTIF(Questionnaire_Raw!$U$3:$U$62,2) -> 0 | E9: =COUNTIF(Questionnaire_Raw!$U$3:$U$62,3) -> 0 | F9: =COUNTIF(Questionnaire_Raw!$U$3:$U$62,4) -> 0 | G9: =COUNTIF(Questionnaire_Raw!$U$3:$U$62,5) -> 0 | H9: =COUNT(Questionnaire_Raw!$U$3:$U$62) -> 0 | I9: =IF(COUNT(Questionnaire_Raw!$U$3:$U$62)=0,"",MEDIAN(Questionnaire_Raw!$U$3:$U$62)) -> 0
A10: Q15a | B10: Trust electronic more (L) | C10: =COUNTIF(Questionnaire_Raw!$W$3:$W$62,1) -> 0 | D10: =COUNTIF(Questionnaire_Raw!$W$3:$W$62,2) -> 0 | E10: =COUNTIF(Questionnaire_Raw!$W$3:$W$62,3) -> 0 | F10: =COUNTIF(Questionnaire_Raw!$W$3:$W$62,4) -> 0 | G10: =COUNTIF(Questionnaire_Raw!$W$3:$W$62,5) -> 0 | H10: =COUNT(Questionnaire_Raw!$W$3:$W$62) -> 0 | I10: =IF(COUNT(Questionnaire_Raw!$W$3:$W$62)=0,"",MEDIAN(Questionnaire_Raw!$W$3:$W$62)) -> 0
A11: Q15b | B11: Worried about other uses (L) | C11: =COUNTIF(Questionnaire_Raw!$X$3:$X$62,1) -> 0 | D11: =COUNTIF(Questionnaire_Raw!$X$3:$X$62,2) -> 0 | E11: =COUNTIF(Questionnaire_Raw!$X$3:$X$62,3) -> 0 | F11: =COUNTIF(Questionnaire_Raw!$X$3:$X$62,4) -> 0 | G11: =COUNTIF(Questionnaire_Raw!$X$3:$X$62,5) -> 0 | H11: =COUNT(Questionnaire_Raw!$X$3:$X$62) -> 0 | I11: =IF(COUNT(Questionnaire_Raw!$X$3:$X$62)=0,"",MEDIAN(Questionnaire_Raw!$X$3:$X$62)) -> 0

Sheet Frequencies
A1: Frequency distributions for categorical items — fill 'Option' column with the exact option text, counts compute
A2: NO DATA HAS BEEN ENTERED. Every row below is an empty template. Enter only real responses; never estimate. Participant codes (S01…, G01…, A01…) replace all names.
A4: Item | B4: Option (type exactly as in raw data) | C4: Count | D4: % of valid
A5: Q1 Programme | C5: =IF(B5="","",COUNTIF(Questionnaire_Raw!$D$3:$D$62,B5)) -> 0 | D5: =IF(OR(B5="",COUNTA(Questionnaire_Raw!$D$3:$D$62)=0),"",C5/COUNTA(Questionnaire_Raw!$D$3:$D$62)) -> 0
C6: =IF(B6="","",COUNTIF(Questionnaire_Raw!$D$3:$D$62,B6)) -> 0 | D6: =IF(OR(B6="",COUNTA(Questionnaire_Raw!$D$3:$D$62)=0),"",C6/COUNTA(Questionnaire_Raw!$D$3:$D$62)) -> 0
C7: =IF(B7="","",COUNTIF(Questionnaire_Raw!$D$3:$D$62,B7)) -> 0 | D7: =IF(OR(B7="",COUNTA(Questionnaire_Raw!$D$3:$D$62)=0),"",C7/COUNTA(Questionnaire_Raw!$D$3:$D$62)) -> 0
C8: =IF(B8="","",COUNTIF(Questionnaire_Raw!$D$3:$D$62,B8)) -> 0 | D8: =IF(OR(B8="",COUNTA(Questionnaire_Raw!$D$3:$D$62)=0),"",C8/COUNTA(Questionnaire_Raw!$D$3:$D$62)) -> 0
C9: =IF(B9="","",COUNTIF(Questionnaire_Raw!$D$3:$D$62,B9)) -> 0 | D9: =IF(OR(B9="",COUNTA(Questionnaire_Raw!$D$3:$D$62)=0),"",C9/COUNTA(Questionnaire_Raw!$D$3:$D$62)) -> 0
A10: Q2 Hosteller/Day scholar | C10: =IF(B10="","",COUNTIF(Questionnaire_Raw!$E$3:$E$62,B10)) -> 0 | D10: =IF(OR(B10="",COUNTA(Questionnaire_Raw!$E$3:$E$62)=0),"",C10/COUNTA(Questionnaire_Raw!$E$3:$E$62)) -> 0
C11: =IF(B11="","",COUNTIF(Questionnaire_Raw!$E$3:$E$62,B11)) -> 0 | D11: =IF(OR(B11="",COUNTA(Questionnaire_Raw!$E$3:$E$62)=0),"",C11/COUNTA(Questionnaire_Raw!$E$3:$E$62)) -> 0
C12: =IF(B12="","",COUNTIF(Questionnaire_Raw!$E$3:$E$62,B12)) -> 0 | D12: =IF(OR(B12="",COUNTA(Questionnaire_Raw!$E$3:$E$62)=0),"",C12/COUNTA(Questionnaire_Raw!$E$3:$E$62)) -> 0
C13: =IF(B13="","",COUNTIF(Questionnaire_Raw!$E$3:$E$62,B13)) -> 0 | D13: =IF(OR(B13="",COUNTA(Questionnaire_Raw!$E$3:$E$62)=0),"",C13/COUNTA(Questionnaire_Raw!$E$3:$E$62)) -> 0
C14: =IF(B14="","",COUNTIF(Questionnaire_Raw!$E$3:$E$62,B14)) -> 0 | D14: =IF(OR(B14="",COUNTA(Questionnaire_Raw!$E$3:$E$62)=0),"",C14/COUNTA(Questionnaire_Raw!$E$3:$E$62)) -> 0
A15: Q3 Entries per weekday | C15: =IF(B15="","",COUNTIF(Questionnaire_Raw!$F$3:$F$62,B15)) -> 0 | D15: =IF(OR(B15="",COUNTA(Questionnaire_Raw!$F$3:$F$62)=0),"",C15/COUNTA(Questionnaire_Raw!$F$3:$F$62)) -> 0
C16: =IF(B16="","",COUNTIF(Questionnaire_Raw!$F$3:$F$62,B16)) -> 0 | D16: =IF(OR(B16="",COUNTA(Questionnaire_Raw!$F$3:$F$62)=0),"",C16/COUNTA(Questionnaire_Raw!$F$3:$F$62)) -> 0
C17: =IF(B17="","",COUNTIF(Questionnaire_Raw!$F$3:$F$62,B17)) -> 0 | D17: =IF(OR(B17="",COUNTA(Questionnaire_Raw!$F$3:$F$62)=0),"",C17/COUNTA(Questionnaire_Raw!$F$3:$F$62)) -> 0
C18: =IF(B18="","",COUNTIF(Questionnaire_Raw!$F$3:$F$62,B18)) -> 0 | D18: =IF(OR(B18="",COUNTA(Questionnaire_Raw!$F$3:$F$62)=0),"",C18/COUNTA(Questionnaire_Raw!$F$3:$F$62)) -> 0
C19: =IF(B19="","",COUNTIF(Questionnaire_Raw!$F$3:$F$62,B19)) -> 0 | D19: =IF(OR(B19="",COUNTA(Questionnaire_Raw!$F$3:$F$62)=0),"",C19/COUNTA(Questionnaire_Raw!$F$3:$F$62)) -> 0
A20: Q4 How ID carried | C20: =IF(B20="","",COUNTIF(Questionnaire_Raw!$G$3:$G$62,B20)) -> 0 | D20: =IF(OR(B20="",COUNTA(Questionnaire_Raw!$G$3:$G$62)=0),"",C20/COUNTA(Questionnaire_Raw!$G$3:$G$62)) -> 0
C21: =IF(B21="","",COUNTIF(Questionnaire_Raw!$G$3:$G$62,B21)) -> 0 | D21: =IF(OR(B21="",COUNTA(Questionnaire_Raw!$G$3:$G$62)=0),"",C21/COUNTA(Questionnaire_Raw!$G$3:$G$62)) -> 0
C22: =IF(B22="","",COUNTIF(Questionnaire_Raw!$G$3:$G$62,B22)) -> 0 | D22: =IF(OR(B22="",COUNTA(Questionnaire_Raw!$G$3:$G$62)=0),"",C22/COUNTA(Questionnaire_Raw!$G$3:$G$62)) -> 0
C23: =IF(B23="","",COUNTIF(Questionnaire_Raw!$G$3:$G$62,B23)) -> 0 | D23: =IF(OR(B23="",COUNTA(Questionnaire_Raw!$G$3:$G$62)=0),"",C23/COUNTA(Questionnaire_Raw!$G$3:$G$62)) -> 0
C24: =IF(B24="","",COUNTIF(Questionnaire_Raw!$G$3:$G$62,B24)) -> 0 | D24: =IF(OR(B24="",COUNTA(Questionnaire_Raw!$G$3:$G$62)=0),"",C24/COUNTA(Questionnaire_Raw!$G$3:$G$62)) -> 0
A25: Q5 How closely guard looks | C25: =IF(B25="","",COUNTIF(Questionnaire_Raw!$H$3:$H$62,B25)) -> 0 | D25: =IF(OR(B25="",COUNTA(Questionnaire_Raw!$H$3:$H$62)=0),"",C25/COUNTA(Questionnaire_Raw!$H$3:$H$62)) -> 0
C26: =IF(B26="","",COUNTIF(Questionnaire_Raw!$H$3:$H$62,B26)) -> 0 | D26: =IF(OR(B26="",COUNTA(Questionnaire_Raw!$H$3:$H$62)=0),"",C26/COUNTA(Questionnaire_Raw!$H$3:$H$62)) -> 0
C27: =IF(B27="","",COUNTIF(Questionnaire_Raw!$H$3:$H$62,B27)) -> 0 | D27: =IF(OR(B27="",COUNTA(Questionnaire_Raw!$H$3:$H$62)=0),"",C27/COUNTA(Questionnaire_Raw!$H$3:$H$62)) -> 0
C28: =IF(B28="","",COUNTIF(Questionnaire_Raw!$H$3:$H$62,B28)) -> 0 | D28: =IF(OR(B28="",COUNTA(Questionnaire_Raw!$H$3:$H$62)=0),"",C28/COUNTA(Questionnaire_Raw!$H$3:$H$62)) -> 0
C29: =IF(B29="","",COUNTIF(Questionnaire_Raw!$H$3:$H$62,B29)) -> 0 | D29: =IF(OR(B29="",COUNTA(Questionnaire_Raw!$H$3:$H$62)=0),"",C29/COUNTA(Questionnaire_Raw!$H$3:$H$62)) -> 0
A30: Q11a Peak wait time | C30: =IF(B30="","",COUNTIF(Questionnaire_Raw!$I$3:$I$62,B30)) -> 0 | D30: =IF(OR(B30="",COUNTA(Questionnaire_Raw!$I$3:$I$62)=0),"",C30/COUNTA(Questionnaire_Raw!$I$3:$I$62)) -> 0
C31: =IF(B31="","",COUNTIF(Questionnaire_Raw!$I$3:$I$62,B31)) -> 0 | D31: =IF(OR(B31="",COUNTA(Questionnaire_Raw!$I$3:$I$62)=0),"",C31/COUNTA(Questionnaire_Raw!$I$3:$I$62)) -> 0
C32: =IF(B32="","",COUNTIF(Questionnaire_Raw!$I$3:$I$62,B32)) -> 0 | D32: =IF(OR(B32="",COUNTA(Questionnaire_Raw!$I$3:$I$62)=0),"",C32/COUNTA(Questionnaire_Raw!$I$3:$I$62)) -> 0
C33: =IF(B33="","",COUNTIF(Questionnaire_Raw!$I$3:$I$62,B33)) -> 0 | D33: =IF(OR(B33="",COUNTA(Questionnaire_Raw!$I$3:$I$62)=0),"",C33/COUNTA(Questionnaire_Raw!$I$3:$I$62)) -> 0
C34: =IF(B34="","",COUNTIF(Questionnaire_Raw!$I$3:$I$62,B34)) -> 0 | D34: =IF(OR(B34="",COUNTA(Questionnaire_Raw!$I$3:$I$62)=0),"",C34/COUNTA(Questionnaire_Raw!$I$3:$I$62)) -> 0
A35: Q6 Times without ID last month | C35: =IF(B35="","",COUNTIF(Questionnaire_Raw!$K$3:$K$62,B35)) -> 0 | D35: =IF(OR(B35="",COUNTA(Questionnaire_Raw!$K$3:$K$62)=0),"",C35/COUNTA(Questionnaire_Raw!$K$3:$K$62)) -> 0
C36: =IF(B36="","",COUNTIF(Questionnaire_Raw!$K$3:$K$62,B36)) -> 0 | D36: =IF(OR(B36="",COUNTA(Questionnaire_Raw!$K$3:$K$62)=0),"",C36/COUNTA(Questionnaire_Raw!$K$3:$K$62)) -> 0
C37: =IF(B37="","",COUNTIF(Questionnaire_Raw!$K$3:$K$62,B37)) -> 0 | D37: =IF(OR(B37="",COUNTA(Questionnaire_Raw!$K$3:$K$62)=0),"",C37/COUNTA(Questionnaire_Raw!$K$3:$K$62)) -> 0
C38: =IF(B38="","",COUNTIF(Questionnaire_Raw!$K$3:$K$62,B38)) -> 0 | D38: =IF(OR(B38="",COUNTA(Questionnaire_Raw!$K$3:$K$62)=0),"",C38/COUNTA(Questionnaire_Raw!$K$3:$K$62)) -> 0
C39: =IF(B39="","",COUNTIF(Questionnaire_Raw!$K$3:$K$62,B39)) -> 0 | D39: =IF(OR(B39="",COUNTA(Questionnaire_Raw!$K$3:$K$62)=0),"",C39/COUNTA(Questionnaire_Raw!$K$3:$K$62)) -> 0
A40: Q9 Ever lost ID | C40: =IF(B40="","",COUNTIF(Questionnaire_Raw!$N$3:$N$62,B40)) -> 0 | D40: =IF(OR(B40="",COUNTA(Questionnaire_Raw!$N$3:$N$62)=0),"",C40/COUNTA(Questionnaire_Raw!$N$3:$N$62)) -> 0
C41: =IF(B41="","",COUNTIF(Questionnaire_Raw!$N$3:$N$62,B41)) -> 0 | D41: =IF(OR(B41="",COUNTA(Questionnaire_Raw!$N$3:$N$62)=0),"",C41/COUNTA(Questionnaire_Raw!$N$3:$N$62)) -> 0
...

Sheet Interview_Notes
A1: Interview notes and open coding — one row per question per interview
A2: NO DATA HAS BEEN ENTERED. Every row below is an empty template. Enter only real responses; never estimate. Participant codes (S01…, G01…, A01…) replace all names.
A3: Interview code | B3: Date | C3: Role (Guard/Admin) | D3: Shift | E3: Gate type | F3: Years exp. | G3: Audio consent | H3: Question # | I3: Note / paraphrase | J3: Verbatim quote (if any) | K3: Initial code | L3: Theme | M3: Links to requirement
A4: G01 | C4: Guard | H4: Q1
A5: G01 | C5: Guard | H5: Q2
A6: G01 | C6: Guard | H6: Q3
A7: G01 | C7: Guard | H7: Q4
A8: G01 | C8: Guard | H8: Q5
A9: G01 | C9: Guard | H9: Q6
A10: G01 | C10: Guard | H10: Q7
A11: G01 | C11: Guard | H11: Q8
A12: G01 | C12: Guard | H12: Q9
A13: G01 | C13: Guard | H13: Q10
A14: G01 | C14: Guard | H14: Q11
A15: G01 | C15: Guard | H15: Q12
... A87: G06 | C87: Guard | H87: Q14

Sheet Observation
A1: Contextual inquiry timing sheet — one row per timed person (Appendix D)
A2: NO DATA HAS BEEN ENTERED. Every row below is an empty template. Enter only real responses; never estimate. Participant codes (S01…, G01…, A01…) replace all names.
A3: Session | B3: Date | C3: Window | D3: Gate | E3: Observer A | F3: Observer B | G3: Person # | H3: Code (U/Q/N/V/R) | I3: Seconds T1−T0 | J3: Queue length (2-min mark) | K3: Exception type | L3: Exception duration (s) | M3: Outcome | N3: Environment / process note
A4: S1 | G4: 1
A5: S1 | G5: 2
A6: S1 | G6: 3
A7: S1 | G7: 4
A8: S1 | G8: 5
A9: S1 | G9: 6
A10: S1 | G10: 7
A11: S1 | G11: 8
A12: S1 | G12: 9
A13: S1 | G13: 10
A14: S1 | G14: 11
A15: S1 | G15: 12
... A123: S3 | G123: 40

Sheet Affinity_Themes
A1: Affinity analysis output
A2: NO DATA HAS BEEN ENTERED. Every row below is an empty template. Enter only real responses; never estimate. Participant codes (S01…, G01…, A01…) replace all names.
A3: Theme code | B3: Theme (user-voice label) | C3: Category (pain/security/privacy/usability/accessibility/opportunity) | D3: Supporting codes (count) | E3: Sources (participant codes) | F3: Representative quote | G3: Confirms / refutes hypothesis (H1-H9) | H3: Links to requirement(s) | I3: Links to screen(s)
A4: T1
A5: T2
A6: T3
A7: T4
A8: T5
A9: T6
A10: T7
A11: T8
A12: T9
A13: T10
A14: T11
A15: T12
... A18: T15

Sheet Hypothesis_Verdicts
A1: Hypotheses from Section 8 — update after analysis
A2: Hypothesis | B2: Statement | C2: Verdict (CONFIRMED / REFUTED / MODIFIED / NO DATA) | D2: Evidence (question, session, quote codes) | E2: Effect on requirements
A3: H1 | B3: Card retrieval delays queue | C3: NO DATA
A4: H2 | B4: Guards do not read expiry | C4: NO DATA
A5: H3 | B5: Face familiarity replaces card check | C5: NO DATA
A6: H4 | B6: Forgotten ID common; inconsistent handling | C6: NO DATA
A7: H5 | B7: Lost cards not blocked; slow replacement | C7: NO DATA
A8: H6 | B8: Visitor register slow; leaks phone numbers | C8: NO DATA
A9: H7 | B9: Peak pressure → waving through | C9: NO DATA
A10: H8 | B10: No record for incidents | C10: NO DATA
A11: H9 | B11: Students uneasy about data use | C11: NO DATA
